[2025-04-06T02:01:47.237+0000] {taskinstance.py:1083} INFO - Dependencies all met for <TaskInstance: alpha_vantage_pipeline.load_forex scheduled__2025-04-06T01:30:00+00:00 [queued]>
[2025-04-06T02:01:47.250+0000] {taskinstance.py:1083} INFO - Dependencies all met for <TaskInstance: alpha_vantage_pipeline.load_forex scheduled__2025-04-06T01:30:00+00:00 [queued]>
[2025-04-06T02:01:47.250+0000] {taskinstance.py:1279} INFO - 
--------------------------------------------------------------------------------
[2025-04-06T02:01:47.250+0000] {taskinstance.py:1280} INFO - Starting attempt 1 of 2
[2025-04-06T02:01:47.250+0000] {taskinstance.py:1281} INFO - 
--------------------------------------------------------------------------------
[2025-04-06T02:01:47.271+0000] {taskinstance.py:1300} INFO - Executing <Task(GCSToBigQueryOperator): load_forex> on 2025-04-06 01:30:00+00:00
[2025-04-06T02:01:47.284+0000] {standard_task_runner.py:55} INFO - Started process 403 to run task
[2025-04-06T02:01:47.289+0000] {standard_task_runner.py:82} INFO - Running: ['***', 'tasks', 'run', 'alpha_vantage_pipeline', 'load_forex', 'scheduled__2025-04-06T01:30:00+00:00', '--job-id', '278', '--raw', '--subdir', 'DAGS_FOLDER/alpha_vantage_pipeline.py', '--cfg-path', '/tmp/tmpccrg4e18']
[2025-04-06T02:01:47.291+0000] {standard_task_runner.py:83} INFO - Job 278: Subtask load_forex
[2025-04-06T02:01:47.414+0000] {task_command.py:388} INFO - Running <TaskInstance: alpha_vantage_pipeline.load_forex scheduled__2025-04-06T01:30:00+00:00 [running]> on host aca641349d5d
[2025-04-06T02:01:47.524+0000] {taskinstance.py:1509} INFO - Exporting the following env vars:
AIRFLOW_CTX_DAG_OWNER=***
AIRFLOW_CTX_DAG_ID=alpha_vantage_pipeline
AIRFLOW_CTX_TASK_ID=load_forex
AIRFLOW_CTX_EXECUTION_DATE=2025-04-06T01:30:00+00:00
AIRFLOW_CTX_TRY_NUMBER=1
AIRFLOW_CTX_DAG_RUN_ID=scheduled__2025-04-06T01:30:00+00:00
[2025-04-06T02:01:47.540+0000] {base.py:73} INFO - Using connection ID 'google_cloud_default' for task execution.
[2025-04-06T02:01:47.543+0000] {gcs_to_bigquery.py:377} INFO - Using existing BigQuery table for storing data...
[2025-04-06T02:01:47.544+0000] {credentials_provider.py:323} INFO - Getting connection using `google.auth.default()` since no key file is defined for hook.
[2025-04-06T02:01:47.650+0000] {gcs_to_bigquery.py:381} INFO - Executing: {'load': {'autodetect': True, 'createDisposition': 'CREATE_IF_NEEDED', 'destinationTable': {'projectId': 'finflow-455108', 'datasetId': 'my_dataset', 'tableId': 'final_table_forex'}, 'sourceFormat': 'CSV', 'sourceUris': ['gs://finflow-455108-data-lake/raw/alpha_vantage/AUD_CNY/*.csv', 'gs://finflow-455108-data-lake/raw/alpha_vantage/USD_CNY/*.csv'], 'writeDisposition': 'WRITE_TRUNCATE', 'ignoreUnknownValues': False, 'skipLeadingRows': None, 'fieldDelimiter': ',', 'quote': None, 'allowQuotedNewlines': False, 'encoding': 'UTF-8'}}
[2025-04-06T02:01:47.651+0000] {bigquery.py:1542} INFO - Inserting job ***_alpha_vantage_pipeline_load_forex_2025_04_06T01_30_00_00_00_6c1dd6b395a288c86383331ac0e38273
[2025-04-06T02:01:49.013+0000] {taskinstance.py:1768} ERROR - Task failed with exception
Traceback (most recent call last):
  File "/home/airflow/.local/lib/python3.7/site-packages/airflow/providers/google/cloud/transfers/gcs_to_bigquery.py", line 440, in execute
    job.result(timeout=self.result_timeout, retry=self.result_retry)
  File "/home/airflow/.local/lib/python3.7/site-packages/google/cloud/bigquery/job/base.py", line 728, in result
    return super(_AsyncJob, self).result(timeout=timeout, **kwargs)
  File "/home/airflow/.local/lib/python3.7/site-packages/google/api_core/future/polling.py", line 137, in result
    raise self._exception
google.api_core.exceptions.NotFound: 404 Not found: Uris gs://finflow-455108-data-lake/raw/alpha_vantage/USD_CNY/*.csv,gs://finflow-455108-data-lake/raw/alpha_vantage/AUD_CNY/*.csv
[2025-04-06T02:01:49.027+0000] {taskinstance.py:1323} INFO - Marking task as UP_FOR_RETRY. dag_id=alpha_vantage_pipeline, task_id=load_forex, execution_date=20250406T013000, start_date=20250406T020147, end_date=20250406T020149
[2025-04-06T02:01:49.055+0000] {standard_task_runner.py:105} ERROR - Failed to execute job 278 for task load_forex (404 Not found: Uris gs://finflow-455108-data-lake/raw/alpha_vantage/USD_CNY/*.csv,gs://finflow-455108-data-lake/raw/alpha_vantage/AUD_CNY/*.csv; 403)
[2025-04-06T02:01:49.085+0000] {local_task_job.py:208} INFO - Task exited with return code 1
[2025-04-06T02:01:49.111+0000] {taskinstance.py:2578} INFO - 0 downstream tasks scheduled from follow-on schedule check
