[2025-04-05T11:40:35.036+0000] {taskinstance.py:1083} INFO - Dependencies all met for <TaskInstance: alpha_vantage_pipeline.load_to_bq manual__2025-04-05T11:33:00.850600+00:00 [queued]>
[2025-04-05T11:40:35.090+0000] {taskinstance.py:1083} INFO - Dependencies all met for <TaskInstance: alpha_vantage_pipeline.load_to_bq manual__2025-04-05T11:33:00.850600+00:00 [queued]>
[2025-04-05T11:40:35.090+0000] {taskinstance.py:1279} INFO - 
--------------------------------------------------------------------------------
[2025-04-05T11:40:35.091+0000] {taskinstance.py:1280} INFO - Starting attempt 2 of 2
[2025-04-05T11:40:35.091+0000] {taskinstance.py:1281} INFO - 
--------------------------------------------------------------------------------
[2025-04-05T11:40:35.176+0000] {taskinstance.py:1300} INFO - Executing <Task(GCSToBigQueryOperator): load_to_bq> on 2025-04-05 11:33:00.850600+00:00
[2025-04-05T11:40:35.195+0000] {standard_task_runner.py:55} INFO - Started process 185 to run task
[2025-04-05T11:40:35.207+0000] {standard_task_runner.py:82} INFO - Running: ['***', 'tasks', 'run', 'alpha_vantage_pipeline', 'load_to_bq', 'manual__2025-04-05T11:33:00.850600+00:00', '--job-id', '152', '--raw', '--subdir', 'DAGS_FOLDER/alpha_vantage_pipeline.py', '--cfg-path', '/tmp/tmpra9vm0rb']
[2025-04-05T11:40:35.211+0000] {standard_task_runner.py:83} INFO - Job 152: Subtask load_to_bq
[2025-04-05T11:40:35.719+0000] {task_command.py:388} INFO - Running <TaskInstance: alpha_vantage_pipeline.load_to_bq manual__2025-04-05T11:33:00.850600+00:00 [running]> on host b341f586e4c9
[2025-04-05T11:40:36.307+0000] {taskinstance.py:1509} INFO - Exporting the following env vars:
AIRFLOW_CTX_DAG_OWNER=***
AIRFLOW_CTX_DAG_ID=alpha_vantage_pipeline
AIRFLOW_CTX_TASK_ID=load_to_bq
AIRFLOW_CTX_EXECUTION_DATE=2025-04-05T11:33:00.850600+00:00
AIRFLOW_CTX_TRY_NUMBER=2
AIRFLOW_CTX_DAG_RUN_ID=manual__2025-04-05T11:33:00.850600+00:00
[2025-04-05T11:40:36.386+0000] {base.py:73} INFO - Using connection ID 'google_cloud_default' for task execution.
[2025-04-05T11:40:36.392+0000] {gcs_to_bigquery.py:377} INFO - Using existing BigQuery table for storing data...
[2025-04-05T11:40:36.397+0000] {credentials_provider.py:323} INFO - Getting connection using `google.auth.default()` since no key file is defined for hook.
[2025-04-05T11:40:36.798+0000] {gcs_to_bigquery.py:381} INFO - Executing: {'load': {'autodetect': True, 'createDisposition': 'CREATE_IF_NEEDED', 'destinationTable': {'projectId': 'finflow-455108', 'datasetId': 'my_dataset', 'tableId': 'final_table'}, 'sourceFormat': 'CSV', 'sourceUris': ['gs://finflow-455108-data-lake/raw/alpha_vantage/*.csv'], 'writeDisposition': 'WRITE_TRUNCATE', 'ignoreUnknownValues': False, 'skipLeadingRows': None, 'fieldDelimiter': ',', 'quote': None, 'allowQuotedNewlines': False, 'encoding': 'UTF-8'}}
[2025-04-05T11:40:36.808+0000] {bigquery.py:1542} INFO - Inserting job ***_alpha_vantage_pipeline_load_to_bq_2025_04_05T11_33_00_850600_00_00_c45bfe477665b89c77158ce62314debd
[2025-04-05T11:40:38.996+0000] {taskinstance.py:1768} ERROR - Task failed with exception
Traceback (most recent call last):
  File "/home/airflow/.local/lib/python3.7/site-packages/airflow/providers/google/cloud/transfers/gcs_to_bigquery.py", line 440, in execute
    job.result(timeout=self.result_timeout, retry=self.result_retry)
  File "/home/airflow/.local/lib/python3.7/site-packages/google/cloud/bigquery/job/base.py", line 728, in result
    return super(_AsyncJob, self).result(timeout=timeout, **kwargs)
  File "/home/airflow/.local/lib/python3.7/site-packages/google/api_core/future/polling.py", line 137, in result
    raise self._exception
google.api_core.exceptions.BadRequest: 400 Error while reading data, error message: CSV table encountered too many errors, giving up. Rows: 0; errors: 100. Please look into the errors[] collection for more details. File: gs://finflow-455108-data-lake/raw/alpha_vantage/AAPL/2025-04-05-11-13.csv
[2025-04-05T11:40:39.043+0000] {taskinstance.py:1323} INFO - Marking task as FAILED. dag_id=alpha_vantage_pipeline, task_id=load_to_bq, execution_date=20250405T113300, start_date=20250405T114035, end_date=20250405T114039
[2025-04-05T11:40:39.174+0000] {standard_task_runner.py:105} ERROR - Failed to execute job 152 for task load_to_bq (400 Error while reading data, error message: CSV table encountered too many errors, giving up. Rows: 0; errors: 100. Please look into the errors[] collection for more details. File: gs://finflow-455108-data-lake/raw/alpha_vantage/AAPL/2025-04-05-11-13.csv; 185)
[2025-04-05T11:40:39.261+0000] {local_task_job.py:208} INFO - Task exited with return code 1
[2025-04-05T11:40:39.335+0000] {taskinstance.py:2578} INFO - 0 downstream tasks scheduled from follow-on schedule check
