[2025-04-05T11:13:44.561+0000] {taskinstance.py:1083} INFO - Dependencies all met for <TaskInstance: alpha_vantage_pipeline.analysis_task manual__2025-04-05T11:13:14.349807+00:00 [queued]>
[2025-04-05T11:13:44.569+0000] {taskinstance.py:1083} INFO - Dependencies all met for <TaskInstance: alpha_vantage_pipeline.analysis_task manual__2025-04-05T11:13:14.349807+00:00 [queued]>
[2025-04-05T11:13:44.569+0000] {taskinstance.py:1279} INFO - 
--------------------------------------------------------------------------------
[2025-04-05T11:13:44.569+0000] {taskinstance.py:1280} INFO - Starting attempt 1 of 2
[2025-04-05T11:13:44.569+0000] {taskinstance.py:1281} INFO - 
--------------------------------------------------------------------------------
[2025-04-05T11:13:44.581+0000] {taskinstance.py:1300} INFO - Executing <Task(PythonOperator): analysis_task> on 2025-04-05 11:13:14.349807+00:00
[2025-04-05T11:13:44.589+0000] {standard_task_runner.py:55} INFO - Started process 274 to run task
[2025-04-05T11:13:44.592+0000] {standard_task_runner.py:82} INFO - Running: ['***', 'tasks', 'run', 'alpha_vantage_pipeline', 'analysis_task', 'manual__2025-04-05T11:13:14.349807+00:00', '--job-id', '137', '--raw', '--subdir', 'DAGS_FOLDER/alpha_vantage_pipeline.py', '--cfg-path', '/tmp/tmp14tr7nwb']
[2025-04-05T11:13:44.593+0000] {standard_task_runner.py:83} INFO - Job 137: Subtask analysis_task
[2025-04-05T11:13:44.649+0000] {task_command.py:388} INFO - Running <TaskInstance: alpha_vantage_pipeline.analysis_task manual__2025-04-05T11:13:14.349807+00:00 [running]> on host 31979a116a32
[2025-04-05T11:13:44.713+0000] {taskinstance.py:1509} INFO - Exporting the following env vars:
AIRFLOW_CTX_DAG_OWNER=***
AIRFLOW_CTX_DAG_ID=alpha_vantage_pipeline
AIRFLOW_CTX_TASK_ID=analysis_task
AIRFLOW_CTX_EXECUTION_DATE=2025-04-05T11:13:14.349807+00:00
AIRFLOW_CTX_TRY_NUMBER=1
AIRFLOW_CTX_DAG_RUN_ID=manual__2025-04-05T11:13:14.349807+00:00
[2025-04-05T11:13:45.876+0000] {taskinstance.py:1768} ERROR - Task failed with exception
Traceback (most recent call last):
  File "/home/airflow/.local/lib/python3.7/site-packages/airflow/operators/python.py", line 175, in execute
    return_value = self.execute_callable()
  File "/home/airflow/.local/lib/python3.7/site-packages/airflow/operators/python.py", line 192, in execute_callable
    return self.python_callable(*self.op_args, **self.op_kwargs)
  File "/opt/airflow/dags/alpha_vantage_pipeline.py", line 46, in do_analysis
    rows = bq_client.query(query).result()
  File "/home/airflow/.local/lib/python3.7/site-packages/google/cloud/bigquery/job/query.py", line 1499, in result
    do_get_result()
  File "/home/airflow/.local/lib/python3.7/site-packages/google/api_core/retry.py", line 288, in retry_wrapped_func
    on_error=on_error,
  File "/home/airflow/.local/lib/python3.7/site-packages/google/api_core/retry.py", line 190, in retry_target
    return target()
  File "/home/airflow/.local/lib/python3.7/site-packages/google/cloud/bigquery/job/query.py", line 1489, in do_get_result
    super(QueryJob, self).result(retry=retry, timeout=timeout)
  File "/home/airflow/.local/lib/python3.7/site-packages/google/cloud/bigquery/job/base.py", line 728, in result
    return super(_AsyncJob, self).result(timeout=timeout, **kwargs)
  File "/home/airflow/.local/lib/python3.7/site-packages/google/api_core/future/polling.py", line 137, in result
    raise self._exception
google.api_core.exceptions.BadRequest: 400 Unrecognized name: symbol at [2:12]

Location: us-central1
Job ID: 6ed4a4db-5d77-417a-8dc7-635f23020f27

[2025-04-05T11:13:45.888+0000] {taskinstance.py:1323} INFO - Marking task as UP_FOR_RETRY. dag_id=alpha_vantage_pipeline, task_id=analysis_task, execution_date=20250405T111314, start_date=20250405T111344, end_date=20250405T111345
[2025-04-05T11:13:45.899+0000] {standard_task_runner.py:105} ERROR - Failed to execute job 137 for task analysis_task (400 Unrecognized name: symbol at [2:12]

Location: us-central1
Job ID: 6ed4a4db-5d77-417a-8dc7-635f23020f27
; 274)
[2025-04-05T11:13:45.926+0000] {local_task_job.py:208} INFO - Task exited with return code 1
[2025-04-05T11:13:45.944+0000] {taskinstance.py:2578} INFO - 0 downstream tasks scheduled from follow-on schedule check
