[2025-04-05T07:30:11.356+0000] {taskinstance.py:1083} INFO - Dependencies all met for <TaskInstance: alpha_vantage_pipeline.dbt_run scheduled__2025-04-05T07:00:00+00:00 [queued]>
[2025-04-05T07:30:11.368+0000] {taskinstance.py:1083} INFO - Dependencies all met for <TaskInstance: alpha_vantage_pipeline.dbt_run scheduled__2025-04-05T07:00:00+00:00 [queued]>
[2025-04-05T07:30:11.368+0000] {taskinstance.py:1279} INFO - 
--------------------------------------------------------------------------------
[2025-04-05T07:30:11.369+0000] {taskinstance.py:1280} INFO - Starting attempt 1 of 2
[2025-04-05T07:30:11.369+0000] {taskinstance.py:1281} INFO - 
--------------------------------------------------------------------------------
[2025-04-05T07:30:11.393+0000] {taskinstance.py:1300} INFO - Executing <Task(PythonOperator): dbt_run> on 2025-04-05 07:00:00+00:00
[2025-04-05T07:30:11.412+0000] {standard_task_runner.py:55} INFO - Started process 999 to run task
[2025-04-05T07:30:11.422+0000] {standard_task_runner.py:82} INFO - Running: ['***', 'tasks', 'run', 'alpha_vantage_pipeline', 'dbt_run', 'scheduled__2025-04-05T07:00:00+00:00', '--job-id', '32', '--raw', '--subdir', 'DAGS_FOLDER/alpha_vantage_pipeline.py', '--cfg-path', '/tmp/tmpkcwg8d2p']
[2025-04-05T07:30:11.428+0000] {standard_task_runner.py:83} INFO - Job 32: Subtask dbt_run
[2025-04-05T07:30:11.496+0000] {task_command.py:388} INFO - Running <TaskInstance: alpha_vantage_pipeline.dbt_run scheduled__2025-04-05T07:00:00+00:00 [running]> on host 4cd87f052cac
[2025-04-05T07:30:11.569+0000] {taskinstance.py:1509} INFO - Exporting the following env vars:
AIRFLOW_CTX_DAG_OWNER=***
AIRFLOW_CTX_DAG_ID=alpha_vantage_pipeline
AIRFLOW_CTX_TASK_ID=dbt_run
AIRFLOW_CTX_EXECUTION_DATE=2025-04-05T07:00:00+00:00
AIRFLOW_CTX_TRY_NUMBER=1
AIRFLOW_CTX_DAG_RUN_ID=scheduled__2025-04-05T07:00:00+00:00
[2025-04-05T07:30:14.140+0000] {taskinstance.py:1768} ERROR - Task failed with exception
Traceback (most recent call last):
  File "/home/airflow/.local/lib/python3.7/site-packages/airflow/operators/python.py", line 175, in execute
    return_value = self.execute_callable()
  File "/home/airflow/.local/lib/python3.7/site-packages/airflow/operators/python.py", line 192, in execute_callable
    return self.python_callable(*self.op_args, **self.op_kwargs)
  File "/opt/airflow/dags/alpha_vantage_pipeline.py", line 28, in dbt_run
    subprocess.run(cmd, check=True)
  File "/usr/local/lib/python3.7/subprocess.py", line 512, in run
    output=stdout, stderr=stderr)
subprocess.CalledProcessError: Command '['dbt', 'run', '--profiles-dir', '.', '--project-dir', '/opt/airflow/dbt']' returned non-zero exit status 2.
[2025-04-05T07:30:14.151+0000] {taskinstance.py:1323} INFO - Marking task as UP_FOR_RETRY. dag_id=alpha_vantage_pipeline, task_id=dbt_run, execution_date=20250405T070000, start_date=20250405T073011, end_date=20250405T073014
[2025-04-05T07:30:14.163+0000] {standard_task_runner.py:105} ERROR - Failed to execute job 32 for task dbt_run (Command '['dbt', 'run', '--profiles-dir', '.', '--project-dir', '/opt/airflow/dbt']' returned non-zero exit status 2.; 999)
[2025-04-05T07:30:14.213+0000] {local_task_job.py:208} INFO - Task exited with return code 1
[2025-04-05T07:30:14.238+0000] {taskinstance.py:2578} INFO - 0 downstream tasks scheduled from follow-on schedule check
